from unittest import TestCase


class Test(TestCase):
    def test_exception_catch(self):
        self.fail()
